Workbook

Sheet Dashboard
A1: Dashboard de seguimiento y evaluación del Plan de Efectividad
A2: BGU · Ciclo académico 01/09/2025 – 31/08/2026
A4: Seleccione el corte para lectura del dashboard | E4: C1 - Diciembre
B6: Total indicadores | E6: Mensuales | H6: Semestrales | K6: Anuales
B7: =COUNTA('Indicadores Master'!$D$2:$D$65) -> 64 | E7: =COUNTIF('Indicadores Master'!$K$2:$K$65,"Mensual") -> 2 | H7: =COUNTIF('Indicadores Master'!$K$2:$K$65,"Semestral") -> 3 | K7: =COUNTIF('Indicadores Master'!$K$2:$K$65,"Anual") -> 59
A11: Resumen del corte seleccionado | D11: Cumplimiento por dimensión (según corte seleccionado) | J11: Distribución del juicio evaluativo
A13: Indicador | B13: Valor | D13: Dimensión | E13: Cumple | F13: En riesgo | G13: No cumple | H13: Pendiente
A14: Indicadores con juicio "Cumple" | B14: =IF($E$4="C1 - Diciembre",COUNTIF('Evaluación Cortes Semestrales'!$I$5:$I$68,"Cumple"),IF($E$4="C2 - Abril",COUNTIF('Evaluación Cortes Semestrales'!$P$5:$P$68,"Cumple"),COUNTIF('Evaluación Cortes Semestrales'!$W$5:$W$68,"Cumple"))) -> 3 | D14: 1. Portafolio Académico | E14: =IF($E$4="C1 - Diciembre",SUMPRODUCT(('Evaluación Cortes Semestrales'!$B$5:$B$68=D14)*('Evaluación Cortes Semestrales'!$I$5:$I$68="Cumple")),IF($E$4="C2 - Abril",SUMPRODUCT(('Evaluación Cortes Semestrales'!$B$5:$B$68=D14)*('Evaluación Cortes Semestrales'!$P$5:$P$68="Cumple")),SUMPRODUCT(('Evaluación Cortes Semestrales'!$B$5:$B$68=D14)*('Evaluación Cortes Semestrales'!$W$5:$W$68="Cumple")))) -> 0 | F14: =IF($E$4="C1 - Diciembre",SUMPRODUCT(('Evaluación Cortes Semestrales'!$B$5:$B$68=D14)*('Evaluación Cortes Semestrales'!$I$5:$I$68="En riesgo")),IF($E$4="C2 - Abril",SUMPRODUCT(('Evaluación Cortes Semestrales'!$B$5:$B$68=D14)*('Evaluación Cortes Semestrales'!$P$5:$P$68="En riesgo")),SUMPRODUCT(('Evaluación Cortes Semestrales'!$B$5:$B$68=D14)*('Evaluación Cortes Semestrales'!$W$5:$W$68="En riesgo")))) -> 0 | G14: =IF($E$4="C1 - Diciembre",SUMPRODUCT(('Evaluación Cortes Semestrales'!$B$5:$B$68=D14)*('Evaluación Cortes Semestrales'!$I$5:$I$68="No cumple")),IF($E$4="C2 - Abril",SUMPRODUCT(('Evaluación Cortes Semestrales'!$B$5:$B$68=D14)*('Evaluación Cortes Semestrales'!$P$5:$P$68="No cumple")),SUMPRODUCT(('Evaluación Cortes Semestrales'!$B$5:$B$68=D14)*('Evaluación Cortes Semestrales'!$W$5:$W$68="No cumple")))) -> 0 | H14: =IF($E$4="C1 - Diciembre",SUMPRODUCT(('Evaluación Cortes Semestrales'!$B$5:$B$68=D14)*('Evaluación Cortes Semestrales'!$I$5:$I$68="Pendiente")),IF($E$4="C2 - Abril",SUMPRODUCT(('Evaluación Cortes Semestrales'!$B$5:$B$68=D14)*('Evaluación Cortes Semestrales'!$P$5:$P$68="Pendiente")),SUMPRODUCT(('Evaluación Cortes Semestrales'!$B$5:$B$68=D14)*('Evaluación Cortes Semestrales'!$W$5:$W$68="Pendiente")))) -> 0 | J14: Cumple | K14: =B14 -> 3
A15: Indicadores "En riesgo" | B15: =IF($E$4="C1 - Diciembre",COUNTIF('Evaluación Cortes Semestrales'!$I$5:$I$68,"En riesgo"),IF($E$4="C2 - Abril",COUNTIF('Evaluación Cortes Semestrales'!$P$5:$P$68,"En riesgo"),COUNTIF('Evaluación Cortes Semestrales'!$W$5:$W$68,"En riesgo"))) -> 0 | D15: 2. Claustro Académico | E15: =IF($E$4="C1 - Diciembre",SUMPRODUCT(('Evaluación Cortes Semestrales'!$B$5:$B$68=D15)*('Evaluación Cortes Semestrales'!$I$5:$I$68="Cumple")),IF($E$4="C2 - Abril",SUMPRODUCT(('Evaluación Cortes Semestrales'!$B$5:$B$68=D15)*('Evaluación Cortes Semestrales'!$P$5:$P$68="Cumple")),SUMPRODUCT(('Evaluación Cortes Semestrales'!$B$5:$B$68=D15)*('Evaluación Cortes Semestrales'!$W$5:$W$68="Cumple")))) -> 1 | F15: =IF($E$4="C1 - Diciembre",SUMPRODUCT(('Evaluación Cortes Semestrales'!$B$5:$B$68=D15)*('Evaluación Cortes Semestrales'!$I$5:$I$68="En riesgo")),IF($E$4="C2 - Abril",SUMPRODUCT(('Evaluación Cortes Semestrales'!$B$5:$B$68=D15)*('Evaluación Cortes Semestrales'!$P$5:$P$68="En riesgo")),SUMPRODUCT(('Evaluación Cortes Semestrales'!$B$5:$B$68=D15)*('Evaluación Cortes Semestrales'!$W$5:$W$68="En riesgo")))) -> 0 | G15: =IF($E$4="C1 - Diciembre",SUMPRODUCT(('Evaluación Cortes Semestrales'!$B$5:$B$68=D15)*('Evaluación Cortes Semestrales'!$I$5:$I$68="No cumple")),IF($E$4="C2 - Abril",SUMPRODUCT(('Evaluación Cortes Semestrales'!$B$5:$B$68=D15)*('Evaluación Cortes Semestrales'!$P$5:$P$68="No cumple")),SUMPRODUCT(('Evaluación Cortes Semestrales'!$B$5:$B$68=D15)*('Evaluación Cortes Semestrales'!$W$5:$W$68="No cumple")))) -> 0 | H15: =IF($E$4="C1 - Diciembre",SUMPRODUCT(('Evaluación Cortes Semestrales'!$B$5:$B$68=D15)*('Evaluación Cortes Semestrales'!$I$5:$I$68="Pendiente")),IF($E$4="C2 - Abril",SUMPRODUCT(('Evaluación Cortes Semestrales'!$B$5:$B$68=D15)*('Evaluación Cortes Semestrales'!$P$5:$P$68="Pendiente")),SUMPRODUCT(('Evaluación Cortes Semestrales'!$B$5:$B$68=D15)*('Evaluación Cortes Semestrales'!$W$5:$W$68="Pendiente")))) -> 0 | J15: En riesgo | K15: =B15 -> 0
A16: Indicadores "No cumple" | B16: =IF($E$4="C1 - Diciembre",COUNTIF('Evaluación Cortes Semestrales'!$I$5:$I$68,"No cumple"),IF($E$4="C2 - Abril",COUNTIF('Evaluación Cortes Semestrales'!$P$5:$P$68,"No cumple"),COUNTIF('Evaluación Cortes Semestrales'!$W$5:$W$68,"No cumple"))) -> 1 | D16: 3. Capital Humano (Administrativo) | E16: =IF($E$4="C1 - Diciembre",SUMPRODUCT(('Evaluación Cortes Semestrales'!$B$5:$B$68=D16)*('Evaluación Cortes Semestrales'!$I$5:$I$68="Cumple")),IF($E$4="C2 - Abril",SUMPRODUCT(('Evaluación Cortes Semestrales'!$B$5:$B$68=D16)*('Evaluación Cortes Semestrales'!$P$5:$P$68="Cumple")),SUMPRODUCT(('Evaluación Cortes Semestrales'!$B$5:$B$68=D16)*('Evaluación Cortes Semestrales'!$W$5:$W$68="Cumple")))) -> 0 | F16: =IF($E$4="C1 - Diciembre",SUMPRODUCT(('Evaluación Cortes Semestrales'!$B$5:$B$68=D16)*('Evaluación Cortes Semestrales'!$I$5:$I$68="En riesgo")),IF($E$4="C2 - Abril",SUMPRODUCT(('Evaluación Cortes Semestrales'!$B$5:$B$68=D16)*('Evaluación Cortes Semestrales'!$P$5:$P$68="En riesgo")),SUMPRODUCT(('Evaluación Cortes Semestrales'!$B$5:$B$68=D16)*('Evaluación Cortes Semestrales'!$W$5:$W$68="En riesgo")))) -> 0 | G16: =IF($E$4="C1 - Diciembre",SUMPRODUCT(('Evaluación Cortes Semestrales'!$B$5:$B$68=D16)*('Evaluación Cortes Semestrales'!$I$5:$I$68="No cumple")),IF($E$4="C2 - Abril",SUMPRODUCT(('Evaluación Cortes Semestrales'!$B$5:$B$68=D16)*('Evaluación Cortes Semestrales'!$P$5:$P$68="No cumple")),SUMPRODUCT(('Evaluación Cortes Semestrales'!$B$5:$B$68=D16)*('Evaluación Cortes Semestrales'!$W$5:$W$68="No cumple")))) -> 0 | H16: =IF($E$4="C1 - Diciembre",SUMPRODUCT(('Evaluación Cortes Semestrales'!$B$5:$B$68=D16)*('Evaluación Cortes Semestrales'!$I$5:$I$68="Pendiente")),IF($E$4="C2 - Abril",SUMPRODUCT(('Evaluación Cortes Semestrales'!$B$5:$B$68=D16)*('Evaluación Cortes Semestrales'!$P$5:$P$68="Pendiente")),SUMPRODUCT(('Evaluación Cortes Semestrales'!$B$5:$B$68=D16)*('Evaluación Cortes Semestrales'!$W$5:$W$68="Pendiente")))) -> 0 | J16: No cumple | K16: =B16 -> 1
A17: Indicadores "Pendiente" | B17: =IF($E$4="C1 - Diciembre",COUNTIF('Evaluación Cortes Semestrales'!$I$5:$I$68,"Pendiente"),IF($E$4="C2 - Abril",COUNTIF('Evaluación Cortes Semestrales'!$P$5:$P$68,"Pendiente"),COUNTIF('Evaluación Cortes Semestrales'!$W$5:$W$68,"Pendiente"))) -> 0 | D17: 4. Plataformas Tecnológicas | E17: =IF($E$4="C1 - Diciembre",SUMPRODUCT(('Evaluación Cortes Semestrales'!$B$5:$B$68=D17)*('Evaluación Cortes Semestrales'!$I$5:$I$68="Cumple")),IF($E$4="C2 - Abril",SUMPRODUCT(('Evaluación Cortes Semestrales'!$B$5:$B$68=D17)*('Evaluación Cortes Semestrales'!$P$5:$P$68="Cumple")),SUMPRODUCT(('Evaluación Cortes Semestrales'!$B$5:$B$68=D17)*('Evaluación Cortes Semestrales'!$W$5:$W$68="Cumple")))) -> 2 | F17: =IF($E$4="C1 - Diciembre",SUMPRODUCT(('Evaluación Cortes Semestrales'!$B$5:$B$68=D17)*('Evaluación Cortes Semestrales'!$I$5:$I$68="En riesgo")),IF($E$4="C2 - Abril",SUMPRODUCT(('Evaluación Cortes Semestrales'!$B$5:$B$68=D17)*('Evaluación Cortes Semestrales'!$P$5:$P$68="En riesgo")),SUMPRODUCT(('Evaluación Cortes Semestrales'!$B$5:$B$68=D17)*('Evaluación Cortes Semestrales'!$W$5:$W$68="En riesgo")))) -> 0 | G17: =IF($E$4="C1 - Diciembre",SUMPRODUCT(('Evaluación Cortes Semestrales'!$B$5:$B$68=D17)*('Evaluación Cortes Semestrales'!$I$5:$I$68="No cumple")),IF($E$4="C2 - Abril",SUMPRODUCT(('Evaluación Cortes Semestrales'!$B$5:$B$68=D17)*('Evaluación Cortes Semestrales'!$P$5:$P$68="No cumple")),SUMPRODUCT(('Evaluación Cortes Semestrales'!$B$5:$B$68=D17)*('Evaluación Cortes Semestrales'!$W$5:$W$68="No cumple")))) -> 0 | H17: =IF($E$4="C1 - Diciembre",SUMPRODUCT(('Evaluación Cortes Semestrales'!$B$5:$B$68=D17)*('Evaluación Cortes Semestrales'!$I$5:$I$68="Pendiente")),IF($E$4="C2 - Abril",SUMPRODUCT(('Evaluación Cortes Semestrales'!$B$5:$B$68=D17)*('Evaluación Cortes Semestrales'!$P$5:$P$68="Pendiente")),SUMPRODUCT(('Evaluación Cortes Semestrales'!$B$5:$B$68=D17)*('Evaluación Cortes Semestrales'!$W$5:$W$68="Pendiente")))) -> 0 | J17: Pendiente | K17: =B17 -> 0
A18: Datos completos | B18: =IF($E$4="C1 - Diciembre",COUNTIF('Evaluación Cortes Semestrales'!$H$5:$H$68,"Completo"),IF($E$4="C2 - Abril",COUNTIF('Evaluación Cortes Semestrales'!$O$5:$O$68,"Completo"),COUNTIF('Evaluación Cortes Semestrales'!$V$5:$V$68,"Completo"))) -> 4 | D18: 5. Posicionamiento Global | E18: =IF($E$4="C1 - Diciembre",SUMPRODUCT(('Evaluación Cortes Semestrales'!$B$5:$B$68=D18)*('Evaluación Cortes Semestrales'!$I$5:$I$68="Cumple")),IF($E$4="C2 - Abril",SUMPRODUCT(('Evaluación Cortes Semestrales'!$B$5:$B$68=D18)*('Evaluación Cortes Semestrales'!$P$5:$P$68="Cumple")),SUMPRODUCT(('Evaluación Cortes Semestrales'!$B$5:$B$68=D18)*('Evaluación Cortes Semestrales'!$W$5:$W$68="Cumple")))) -> 0 | F18: =IF($E$4="C1 - Diciembre",SUMPRODUCT(('Evaluación Cortes Semestrales'!$B$5:$B$68=D18)*('Evaluación Cortes Semestrales'!$I$5:$I$68="En riesgo")),IF($E$4="C2 - Abril",SUMPRODUCT(('Evaluación Cortes Semestrales'!$B$5:$B$68=D18)*('Evaluación Cortes Semestrales'!$P$5:$P$68="En riesgo")),SUMPRODUCT(('Evaluación Cortes Semestrales'!$B$5:$B$68=D18)*('Evaluación Cortes Semestrales'!$W$5:$W$68="En riesgo")))) -> 0 | G18: =IF($E$4="C1 - Diciembre",SUMPRODUCT(('Evaluación Cortes Semestrales'!$B$5:$B$68=D18)*('Evaluación Cortes Semestrales'!$I$5:$I$68="No cumple")),IF($E$4="C2 - Abril",SUMPRODUCT(('Evaluación Cortes Semestrales'!$B$5:$B$68=D18)*('Evaluación Cortes Semestrales'!$P$5:$P$68="No cumple")),SUMPRODUCT(('Evaluación Cortes Semestrales'!$B$5:$B$68=D18)*('Evaluación Cortes Semestrales'!$W$5:$W$68="No cumple")))) -> 1 | H18: =IF($E$4="C1 - Diciembre",SUMPRODUCT(('Evaluación Cortes Semestrales'!$B$5:$B$68=D18)*('Evaluación Cortes Semestrales'!$I$5:$I$68="Pendiente")),IF($E$4="C2 - Abril",SUMPRODUCT(('Evaluación Cortes Semestrales'!$B$5:$B$68=D18)*('Evaluación Cortes Semestrales'!$P$5:$P$68="Pendiente")),SUMPRODUCT(('Evaluación Cortes Semestrales'!$B$5:$B$68=D18)*('Evaluación Cortes Semestrales'!$W$5:$W$68="Pendiente")))) -> 0
D19: 6. Cultura Universitaria | E19: =IF($E$4="C1 - Diciembre",SUMPRODUCT(('Evaluación Cortes Semestrales'!$B$5:$B$68=D19)*('Evaluación Cortes Semestrales'!$I$5:$I$68="Cumple")),IF($E$4="C2 - Abril",SUMPRODUCT(('Evaluación Cortes Semestrales'!$B$5:$B$68=D19)*('Evaluación Cortes Semestrales'!$P$5:$P$68="Cumple")),SUMPRODUCT(('Evaluación Cortes Semestrales'!$B$5:$B$68=D19)*('Evaluación Cortes Semestrales'!$W$5:$W$68="Cumple")))) -> 0 | F19: =IF($E$4="C1 - Diciembre",SUMPRODUCT(('Evaluación Cortes Semestrales'!$B$5:$B$68=D19)*('Evaluación Cortes Semestrales'!$I$5:$I$68="En riesgo")),IF($E$4="C2 - Abril",SUMPRODUCT(('Evaluación Cortes Semestrales'!$B$5:$B$68=D19)*('Evaluación Cortes Semestrales'!$P$5:$P$68="En riesgo")),SUMPRODUCT(('Evaluación Cortes Semestrales'!$B$5:$B$68=D19)*('Evaluación Cortes Semestrales'!$W$5:$W$68="En riesgo")))) -> 0 | G19: =IF($E$4="C1 - Diciembre",SUMPRODUCT(('Evaluación Cortes Semestrales'!$B$5:$B$68=D19)*('Evaluación Cortes Semestrales'!$I$5:$I$68="No cumple")),IF($E$4="C2 - Abril",SUMPRODUCT(('Evaluación Cortes Semestrales'!$B$5:$B$68=D19)*('Evaluación Cortes Semestrales'!$P$5:$P$68="No cumple")),SUMPRODUCT(('Evaluación Cortes Semestrales'!$B$5:$B$68=D19)*('Evaluación Cortes Semestrales'!$W$5:$W$68="No cumple")))) -> 0 | H19: =IF($E$4="C1 - Diciembre",SUMPRODUCT(('Evaluación Cortes Semestrales'!$B$5:$B$68=D19)*('Evaluación Cortes Semestrales'!$I$5:$I$68="Pendiente")),IF($E$4="C2 - Abril",SUMPRODUCT(('Evaluación Cortes Semestrales'!$B$5:$B$68=D19)*('Evaluación Cortes Semestrales'!$P$5:$P$68="Pendiente")),SUMPRODUCT(('Evaluación Cortes Semestrales'!$B$5:$B$68=D19)*('Evaluación Cortes Semestrales'!$W$5:$W$68="Pendiente")))) -> 0
D20: 7. Apoyo Económico | E20: =IF($E$4="C1 - Diciembre",SUMPRODUCT(('Evaluación Cortes Semestrales'!$B$5:$B$68=D20)*('Evaluación Cortes Semestrales'!$I$5:$I$68="Cumple")),IF($E$4="C2 - Abril",SUMPRODUCT(('Evaluación Cortes Semestrales'!$B$5:$B$68=D20)*('Evaluación Cortes Semestrales'!$P$5:$P$68="Cumple")),SUMPRODUCT(('Evaluación Cortes Semestrales'!$B$5:$B$68=D20)*('Evaluación Cortes Semestrales'!$W$5:$W$68="Cumple")))) -> 0 | F20: =IF($E$4="C1 - Diciembre",SUMPRODUCT(('Evaluación Cortes Semestrales'!$B$5:$B$68=D20)*('Evaluación Cortes Semestrales'!$I$5:$I$68="En riesgo")),IF($E$4="C2 - Abril",SUMPRODUCT(('Evaluación Cortes Semestrales'!$B$5:$B$68=D20)*('Evaluación Cortes Semestrales'!$P$5:$P$68="En riesgo")),SUMPRODUCT(('Evaluación Cortes Semestrales'!$B$5:$B$68=D20)*('Evaluación Cortes Semestrales'!$W$5:$W$68="En riesgo")))) -> 0 | G20: =IF($E$4="C1 - Diciembre",SUMPRODUCT(('Evaluación Cortes Semestrales'!$B$5:$B$68=D20)*('Evaluación Cortes Semestrales'!$I$5:$I$68="No cumple")),IF($E$4="C2 - Abril",SUMPRODUCT(('Evaluación Cortes Semestrales'!$B$5:$B$68=D20)*('Evaluación Cortes Semestrales'!$P$5:$P$68="No cumple")),SUMPRODUCT(('Evaluación Cortes Semestrales'!$B$5:$B$68=D20)*('Evaluación Cortes Semestrales'!$W$5:$W$68="No cumple")))) -> 0 | H20: =IF($E$4="C1 - Diciembre",SUMPRODUCT(('Evaluación Cortes Semestrales'!$B$5:$B$68=D20)*('Evaluación Cortes Semestrales'!$I$5:$I$68="Pendiente")),IF($E$4="C2 - Abril",SUMPRODUCT(('Evaluación Cortes Semestrales'!$B$5:$B$68=D20)*('Evaluación Cortes Semestrales'!$P$5:$P$68="Pendiente")),SUMPRODUCT(('Evaluación Cortes Semestrales'!$B$5:$B$68=D20)*('Evaluación Cortes Semestrales'!$W$5:$W$68="Pendiente")))) -> 0
J22: Inventario de indicadores por temporalidad
J24: Mensual | K24: 2
J25: Semestral | K25: 3
J26: Anual | K26: 59

Sheet Listas
A1: Juicio evaluativo | B1: Estado del dato | C1: Corte | D1: Semáforo | E1: Temporalidad | F1: Meses
A2: Cumple | B2: Completo | C2: C1 - Diciembre | D2: 🟢 | E2: Mensual | F2: Sep
A3: En riesgo | B3: Parcial | C3: C2 - Abril | D3: 🟡 | E3: Semestral | F3: Oct
A4: No cumple | B4: En levantamiento | C4: C3 - Agosto | D4: 🔴 | E4: Anual | F4: Nov
A5: Pendiente | B5: No recibido | D5: ⚪ | F5: Dic
F6: Ene
F7: Feb
F8: Mar
F9: Abr
F10: May
F11: Jun
F12: Jul
F13: Ago

Sheet Instrucciones
A1: Dashboard de Evaluación del Plan de Efectividad Institucional 2025-2026
A3: Cómo usar este archivo
A5: 1. Revisa la hoja 'Calendario_Cortes' para seguir el ciclo académico de BGU: 01/09 al 31/08.
A7: 2. Usa la hoja 'Indicadores_Master' como referencia oficial del cuadro de dimensiones, metas, fórmula y responsable.
A9: 3. Registra datos recibidos de las divisiones en 'Registro_Datos'. Puedes cargar cada dato mensual, semestral o anual conforme llegue.
A11: 4. En la hoja 'Evaluación_3_Cortes' realiza el análisis formal del plan tres veces al año: C1-Diciembre, C2-Abril y C3-Agosto.
A13: 5. Para cada corte, consigna: valor reportado, estado del dato, juicio evaluativo, análisis, decisión/acción, responsable y fecha compromiso.
A15: 6. El dashboard resume automáticamente el avance del corte seleccionado y te ayuda a presentar resultados con semáforo institucional.
A17: 7. Indicadores anuales: en C1 y C2 puedes marcar 'Pendiente' o 'En levantamiento'; la evaluación final se consolida en C3-Ago.
A21: Criterio sugerido de evaluación
A23: Temporalidad | B23: Qué registrar | C23: Qué analizar en los cortes
A24: Mensual | B24: Dato de cada mes | C24: Analiza tendencia acumulada en C1, C2 y C3
A25: Semestral | B25: Dato al cierre de cada semestre | C25: En C1 usa avance preliminar si aplica; en C2 y C3 incorpora cierres semestrales
A26: Anual | B26: Dato una vez por año | C26: En C1/C2 deja evidencia del levantamiento; en C3 emite juicio final

Sheet Calendario Cortes
A1: Calendario de seguimiento y evaluación — BGU
A3: Ciclo académico | B3: 01 de septiembre al 31 de agosto
A6: Seguimiento | B6: Sep | C6: Oct | D6: Nov | E6: Dic | F6: Ene | G6: Feb | H6: Mar | I6: Abr | J6: May | K6: Jun | L6: Jul | M6: Ago
A7: Recepción de datos mensuales | B7: ● | C7: ● | D7: ● | E7: ● | F7: ● | G7: ● | H7: ● | I7: ● | J7: ● | K7: ● | L7: ● | M7: ●
A8: Recepción de datos semestrales | E8: avance | G8: cierre S1 | M8: cierre S2
A9: Levantamiento de anuales | B9: inicio | C9: ● | D9: ● | E9: ● | F9: ● | G9: ● | H9: ● | I9: ● | J9: ● | K9: ● | L9: ● | M9: cierre
A10: C1 - Evaluación institucional | E10: X
A11: C2 - Evaluación institucional | I11: X
A12: C3 - Evaluación institucional | M12: X
A15: Lectura recomendada por corte
A17: Corte | B17: Ventana de análisis recomendada | C17: Qué debe quedar documentado
A18: C1 - Diciembre | B18: Sep–Dic | C18: avance inicial, desvíos tempranos, acciones de corrección
A19: C2 - Abril | B19: Sep–Abr | C19: tendencia acumulada, primer cierre fuerte, seguimiento de acciones
A20: C3 - Agosto | B20: Sep–Ago | C20: cierre anual, cumplimiento final y lecciones para el siguiente ciclo

Sheet Registro Nuevo - Reporte 2025 -
A1: PLAN DE EFECTIVIDAD 2025 - 2026 EVALUACIÓN DE RESULTADOS 01 de septiembre del 2025 - 31 de agosto del 2026
A3: Estrategia | B3: Objetivo Institucional | C3: N° | D3: Código | E3: Nivel | F3: KPI y alcance | G3: Fórmula | H3: Meta | I3: Tipo de medida | J3: Fuente | K3: Reponsable | L3: Responsable ERP | M3: Frecuencia | N3: Resultados | O3: Evidencia | P3: Brecha | Q3: Estado | S3: Decision
A4: E1. Portafolio Académico | B4: Establecer una comunidad de aprendizaje diversa y global mediante una oferta autorizada, activa, pertinente y sostenible. | C4: 1 | D4: E1-I01 | E4: Intitucional | F4: Oferta efectiva de programas: Proporcion de programas autorizados que se encuentran activos, admiten estudiantes y cuentan con capacidad academica y operativa | G4: Programas activos / programas autorizados x 100 | H4: >=59% | I4: Cuantitativa directa | J4: Plan académico anual; catalogo; registro de programas | K4: Division of Academic Affairs / Division of Admissions and Marketing | L4: Ronald | M4: Semestral | N4: =11/11 -> 1 | O4: Catálogo BGU 12499Approved Data (1).pdf | Q4: Cumplido | R4: TRUE
C5: 2 | D5: E1-I02 | E5: Intitucional | F5: Retention Rate estudiantil: Persistencia de estudiantes elegibles de un periodo al siguiente; debe calcularse por cohorte, nivel y programa. | G5: Dashboard CIE | H5: >=85% | I5: Cuantitativa directa | J5: SIS/SMS; registros del Registrar | K5: Registrar / Division of Student Services | L5: Marisol | M5: Anual | N5: 0.91 | O5: Ratios 801 Data Collection (18.11.25) .xlsx | Q5: Cumplido | R5: TRUE | T5: Estado | U5: Criterio general | V5: Tratamiento | W5: Resultados
C6: 3 | D6: E1-I03 | E6: Intitucional | F6: Graduation Rate: Graduacion dentro de la ventana institucional de reporte, desagregada por nivel y cohorte madura. | G6: Graduados de la cohorte / estudiantes de la cohorte ajustada x 100 | H6: >=70% | I6: Cuantitativa directa | J6: Registros academicos; expedientes de graduación | K6: Registrar / Division of Student Services | L6: Ronald | M6: Anual | N6: 0.56 | O6: Copia de RATIOS DEAC - 24-03-26 Ratios 801 Data Collection (18.11.25) .xlsx | Q6: Parcialmente Cumplido | R6: TRUE | T6: Cumplido | U6: Meta alcanzada o superada, considerando la dirección del KPI. | V6: Mantener, elevar meta o cerrar mejora. | W6: =COUNTIF($Q$4:$Q40,"Cumplido") -> 18
C7: 4 | D7: E1-S01 | E7: Estratégico | F7: Pertinencia curricular internacional: Alineacion de los programas con demanda, regulacion, recomendaciones de advisory councils y resultados de aprendizaje | G7: Promedio de rubrica institucional de pertinencia (1-5) | H7: >=4/5 | I7: Mixta directa e indirecta | J7: Informes de revisión curricular; actas de advisory councils | K7: Division of Academic Affairs | L7: Ronald | M7: Anual | N7: 4.61 | O7: INFORME DE REVISIÓN CURRICULAR DEL PROGRAMA DE.docx | Q7: Cumplido | R7: TRUE | T7: Parcialmente cumplido | U7: Resultado mayor a 0 | V7: Analizar causa y fortalecer acciones. | W7: =COUNTIF($Q$4:$Q40,"Parcialmente cumplido") -> 5
C8: 5 | D8: E1-S02 | E8: Estratégico | F8: Diversidad geografica del alumnado: Cobertura internacional real de la matricula activa | G8: Conteo distinto de países de residencia de estudiantes activos | H8: >=20 países | I8: Cuantitativa directa | J8: Registro de admision; SIS/SMS | K8: Division of Admissions and Marketing / Registrar | L8: Antony Huaynapata | M8: Semestral | N8: 21 | O8: Paises/Registros | P8: 0 | Q8: Cumplido | R8: TRUE | T8: No cumplido | U8: Resultado igual a 0 | V8: Accion de mejora obligatoria cuando proceda. | W8: =COUNTIF($Q$4:$Q40,"No cumplido") -> 11
C9: 6 | D9: E1-O01 | E9: Operativo | F9: Programas autorizados por CIE: Cumplimiento regulatorio del portafolio autorizado. | G9: Conteo oficial a la fecha de corte | H9: >=11 | I9: Cuantitativa directa | J9: Registro público CIE; resoluciones y expedientes | K9: Division of Academic Affairs | L9: Ronald | M9: Anual | N9: 11 | O9: 12499Approved Data (1).pdf | Q9: Cumplido | R9: TRUE | T9: Sin datos | U9: La fuente no produjo informacion valida. | V9: Plan de obtencion y responsable; no registrar cero. | W9: =COUNTIF($Q$4:$Q40,"Sin datos") -> 0
A10: E2. Claustro Académico | B10: Mantener un claustro académico de calidad, suficiente, internacional, evaluado y en desarrollo continuo. | C10: 1 | D10: E2-I01 | E10: Institucional | F10: Evaluacion docente por estudiantes: Valoracion consolidada del desempeno docente en los cursos impartidos. | G10: Suma de puntuaciones validas / número de respuestas validas | H10: >=4/5 | I10: Cuantitativa indirecta | J10: Encuestas finales de curso | K10: Division of Academic Affairs / Division of Student Services | L10: Ronald | M10: Cada termino | N10: 4.54 | O10: Indicadores de Programas de Estudio BGU 2025–2026.pdf | Q10: Cumplido | R10: TRUE | T10: No aplicable / cohorte no madura | U10: El indicador no puede medirse legitimamente en el periodo. | V10: Justificar y programar la primera medición valida. | W10: =COUNTIF($Q$4:$Q40,"No aplicable / cohorte no madura") -> 0
C11: 2 | D11: E2-S01 | E11: Estratégico | F11: Actualizacion pedagogica: Participacion del faculty activo en el plan anual de desarrollo docente. | G11: Faculty que completa el plan / faculty activo x 100 | H11: >=70% | I11: Cuantitativa directa | J11: Registros de capacitación | K11: Division of Continuing Education / Division of Academic Affairs | L11: Ronald | M11: Anual | N11: 1 | O11: Registros de capacitación PLAN ANUAL DE DESARROLLO DOCENTE 2025 - 2026 INFORME DE CUMPLIMIENTO DEL PLAN ANUAL DE DESARROLLO DOCENTE 2025 - 2026 | Q11: Cumplido | R11: TRUE
C12: 3 | D12: E2-S02 | E12: Estratégico | F12: Permanencia docente: Continuidad del faculty elegible de un periodo academico al siguiente. | G12: Faculty que continua / faculty elegible inicial x 100 | H12: >=85% | I12: Cuantitativa directa | J12: Roster docente; contratos; nómina | K12: Division of Academic Affairs / Administration Services and Finance | L12: Ronald | M12: Anual | N12: =42/45 -> 0.93333333 | O12: Permanencia docente: 2025-2026 45 docentes y del 2026- 2027 tenemos 68 de ellos 42 de los 45 continuan | Q12: Cumplido | R12: TRUE | T12: Portafolio Académico | Y12: =IFERROR(__xludf.DUMMYFUNCTION("SPARKLINE(COUNTIF($Q$4:$Q$9,""Sin datos""),{""charttype"",""bar"";""max"",6;""color1"",""#9AA0A6""})"),"")
C13: 4 | D13: E2-O01 | E13: Operativo | F13: Diversidad internacional del claustro: Representacion de nacionalidades y experiencias academicas internacionales en el faculty activo. | G13: Conteo distinto de nacionalidades representadas | H13: >=10 países | I13: Cuantitativa directa | J13: Roster y expedientes de faculty | K13: Division of Academic Affairs | L13: Ronald | M13: Anual | N13: 11 paises | O13: Diversidad internacional del claustro | Q13: Cumplido | R13: TRUE | T13: Claustro Académico
C14: 5 | D14: E2-O02 | E14: Operativo | F14: Profesores Top en actividad: Proporcion de faculty que cumple la definicion institucional vigente y presta servicio academico efectivo en el periodo. | G14: Faculty Top activo / faculty activo x 100 | H14: >=10% | I14: Cuantitativa directa | J14: Expedientes y asignaciones docentes | K14: Division of Academic Affairs | L14: Ronald | M14: Anual | N14: =28/68 -> 0.41176471 | O14: Profesores Top en actividad 28 de 68 docentes | Q14: Cumplido | R14: TRUE | T14: Capital Humano Administrativo
A15: E3. Capital humano administrativo | B15: Contar con personal administrativo competente, estable y orientado a la eficiencia y al servicio. | C15: 1 | D15: E3-I01 | E15: Institucional | F15: Satisfaccion con servicios administrativos: Valoracion global de los servicios administrativos y de apoyo recibidos por los estudiantes | G15: Respuestas favorables / respuestas validas x 10 | H15: >=80% | I15: Cuantitativa indirecta | J15: Encuesta anual de satisfaccion; reporte de servicio | K15: Division of Administration Services and Finance / Division of Student Services | L15: Marisol | M15: Anual | N15: 0.92 | O15: Base Encuesta (8) ¿Qué tan satisfecho/a está con la atención y respuesta del área de soporte o servicios estudiantiles? 112 Encuestados al 14-07 neutral 19 satisfecho 38 muy satisfecho 46 | Q15: Cumplido | R15: TRUE | T15: Plataformas Tecnológicas
C16: 2 | D16: E3-I02 | E16: Institucional | F16: Clima laboral administrativo: Percepcion del staff sobre liderazgo, colaboración, recursos, desarrollo y ambiente laboral. | G16: Respuestas favorables / respuestas validas x 100 | H16: >=85% | I16: Cuantitativa indirecta | J16: Encuesta anual al staff | K16: Division of Administration Services and Finance | L16: Yajayra | M16: Anual | N16: 0.9669 | O16: Informe: Informe del Indicador 3.4 - Clima Laboral Administrativo - Plan de Efectividad 2025-2026 Anual2025 (1).pdf Indice de Satisfaccion (%)=Número total de respuestas/Número de respuestas con valores 3, 4 y 5​×100 Encuesta: ENCUESTA DEL CLIMA LABORAL STAFF - BGU.pdf | Q16: Cumplido | R16: TRUE | T16: Posicionamiento Global
C17: 3 | D17: E3-S01 | E17: Estratégico | F17: Permanencia del personal administrativo: Continuidad del personal elegible durante el periodo. | G17: Staff que continua / staff elegible inicial x 100 | H17: >=85% | I17: Cuantitativa directa | J17: Nómina y registros de recursos humanos | K17: Division of Administration Services and Finance | L17: Yajayra | M17: Anual | N17: 0.77 | O17: Permanencia del Personal Administrativo: Cuadro de asignación de personal y Job Description BGU | Q17: Parcialmente Cumplido | R17: TRUE | T17: Cultura Universitaria
C18: 4 | D18: E3-S02 | E18: Estratégico | F18: Capacitacion administrativa: Cumplimiento del plan anual de capacitación del staff. | G18: Staff que completa capacitación / staff activo x 100 | H18: >=80% | I18: Cuantitativa directa | J18: Registros de capacitación y certificados | K18: Division of Administration Services and Finance | L18: Yajayra | M18: Anual | N18: 0.9333 | O18: Informe con corte a Junio 2026 - 93,33%: Informe del Indicado 3.6 - Capacitación Administrativa | Q18: Cumplido | R18: TRUE | T18: Apoyo Económico y Acceso
C19: 5 | D19: E3-O01 | E19: Operativo | F19: Resolucion en primer contacto: Casos resueltos sin escalamiento ni reapertura dentro del periodo de control. | G19: Casos resueltos en primer contacto / casos cerrados x 100 | H19: >=70% | I19: Cuantitativa directa | J19: Zoho Desk, Bitrix u otro sistema de tickets | K19: Division of Student Services | L19: Marisol | M19: Mensual | O19: Miércoles 22 | Q19: No cumplido | R19: FALSE
C20: 6 | D20: E3-O02 | E20: Operativo | F20: Tiempo medio de respuesta: Tiempo promedio transcurrido entre la recepcion de una solicitud y la primera respuesta util | G20: Suma de horas hasta primera respuesta / solicitudes atendidas | H20: <=6 horas | I20: Cuantitativa directa | J20: Sistema de tickets y reportes de SLA | K20: Division of Student Services | L20: Marisol | M20: Mensual | O20: Miércoles 22 | Q20: No cumplido | R20: FALSE
A21: E4. Plataformas Tecnológicas | B21: Proveer plataformas tecnológicas seguras, disponibles y adoptadas que mejoren aprendizaje y operaciones. | C21: 1 | D21: E4-I01 | E21: Institucional | F21: Satisfaccion general con plataformas LMS/SIS: Valoracion de usabilidad, fiabilidad y experiencia del entorno tecnologico. | G21: Promedio de encuesta institucional (1-5) | H21: >=4/5 | I21: Cuantitativa indirecta | J21: Encuestas institucionales | K21: Division of Student Services / Division of Academic Affairs | L21: Anthony Robles | M21: Anual | N21: 3.97 | O21: https://support.blackwell.university/tech-infrastructure-reports/ | Q21: No cumplido | R21: TRUE
C22: 2 | D22: E4-S01 | E22: Estratégico | F22: Disponibilidad de sistemas criticos (Uptime): Continuidad del servicio en LMS, SIS y otros sistemas definidos como criticos. | G22: Horas disponibles / horas programadas x 100 | H22: >=99.9% | I22: Cuantitativa directa | J22: Logs y reportes de infraestructura | K22: Administration Services and Finance / Technology | L22: Anthony Robles | M22: Mensual | N22: Campus LMS = 99,99% Activa = 99,99% | O22: https://support.blackwell.university/Uptime | Q22: Cumplido | R22: TRUE
C23: 3 | D23: E4-S02 | E23: Estratégico | F23: Seguridad percibida: Confianza de estudiantes y faculty en la proteccion de datos personales y academicos. | G23: Respuestas favorables / respuestas validas x 100 | H23: >=90% | I23: Cuantitativa indirecta | J23: Encuesta anual de tecnologia y privacidad | K23: Division of Student Services / Division of Academic Affairs | L23: Anthony Robles | M23: Anual | N23: 0 | O23: No disponemos de la encuesta. Propuesta: https://support.blackwell.university/it-security/ Políticas de protección de datos y seguridad https://docs.google.com/document/d/1aBR7ldYpulRs7XhVqGswRm3MEF1tLrntJ-Oad22f0jQ/edit?tab=t.0 https://docs.google.com/document/d/1RFrZQHdt4AwnFpWNjISEgZEEMaypGjVfMpqHYNIHxFY/edit?tab=t.0 | Q23: No cumplido | R23: TRUE
C24: 4 | D24: E4-O01 | E24: Operativo | F24: Optimizacion de procesos: Procesos institucionales automatizados o redisenados y puestos en produccion durante el periodo. | G24: Conteo de procesos implementados y validados | H24: >=5 nuevos por año | I24: Cuantitativa directa | J24: Registro de procesos; actas de aceptacion | K24: Administration Services and Finance / Technology | L24: Anthony Robles | M24: Anual | N24: 15 | O24: Formularios Admision Acreditación Proyecto Capstone Chatfuel Master / doctorado / Licenciatura Chatfuel DCE ORA IA BGU Trabajos finales Sesiones Eurocoach Sesiones Mentoring Activa Student / Admin Reporte de Consolidado de Deudas y Recaudación de la Empresa por fechas. Sincronización de alumnos y sus cursos en el Moodle Retiro del estudiante y suspension de acceso al Moodle Sincronizacion de califaciones del moodle a la base de datos Activa Creacion de cuotas del producto y cuenta de google workspace despues de procesar el pago inicial del alumno Envio de correos electronicos con plantillas automaticas segun produto/categoria/empresa | Q24: Cumplido | R24: TRUE
C25: 5 | D25: E4-O02 | E25: Operativo | F25: Adopcion y capacitacion en plataformas: Usuarios obligados que completan la capacitacion anual en EdTech y ciberseguridad. | G25: Usuarios capacitados / usuarios obligados x 100 | H25: >=90% | I25: Cuantitativa directa | J25: LMS de capacitación; certificados | K25: Division of Academic Affairs / Division of Continuing Education | L25: Anthony Robles | M25: Anual | N25: 0 | O25: 0% NUEVO KPI - Por implementar Se gestionará cronograma para la capacitación | Q25: No cumplido | R25: TRUE
A26: E5. Posicionamiento Global | B26: Crear alianzas y oportunidades globales con impacto académico, profesional y reputacional medible. | C26: 1 | D26: E5-I01 | E26: Institucional | F26: Placement Rate: Graduados elegibles que reportan empleo, mejora laboral, emprendimiento o continuidad academica dentro de la ventana definida. | G26: Graduados con resultado favorable / graduados elegibles localizados x 100 | H26: >=85% | I26: Mixta directa e indirecta | J26: Encuesta de egresados; verificacion de Career Service | K26: Division of Student Services | L26: Marisol | M26: Anual | N26: =46/172 -> 0.26744186 | O26: Ratios 801 Data Collection (18.11.25) .xlsx Fueron 46 respuestas Población 172 | Q26: Parcialmente Cumplido | R26: FALSE
C27: 2 | D27: E5-I02 | E27: Institucional | F27: Percepcion de marca global: Reconocimiento y asociacion favorable de BGU entre grupos de interes seleccionados. | G27: Respuestas favorables / respuestas validas x 100 | H27: >=60% | I27: Cuantitativa indirecta | J27: Encuestas a estudiantes, alumni y aliados | K27: Division of Admissions and Marketing | L27: Antony Huaynapata | M27: Anual | N27: 0 | O27: El indicador E5-I02 (Percepción de marca global) no ha sido ejecutado a la fecha debido a que aún no se cuenta con el instrumento de medición (encuesta de percepción de marca) diseñado y aplicado a los grupos de interés. En las encuestas aplicadas hasta el momento por las áreas de Registros (Encuesta de Satisfacción Estudiantil), Servicios al Estudiante (Encuesta de Seguimiento al Egresado - BGU 2025) y Marketing (Buyer Persona), no se ha considerado este ítem. Para su cálculo, se requiere elaborar dicho instrumento, definir los grupos de interés a encuestar y establecer la periodicidad de aplicación. | Q27: No cumplido | R27: TRUE
C28: 3 | D28: E5-S01 | E28: Estratégico | F28: Relevancia de alianzas: Impacto academico, profesional o reputacional de los convenios activos | G28: Promedio de rubrica institucional de impacto (1-5) | H28: >=4/5 | I28: Mixta directa e indirecta | J28: Informe anual de convenios y evidencias de actividad | K28: Division of Admissions and Marketing / Division of Academic Affairs | L28: Ronald | M28: Anual | N28: 4 | O28: RELEVANCIA DE ALIANZAS - RÚBRICA | Q28: Cumplido | R28: TRUE
C29: 4 | D29: E5-S02 | E29: Estratégico | F29: Estudiantes en movilidad o experiencia internacional: Participacion estudiantil en intercambio, movilidad virtual, proyectos o actividades internacionales verificadas | G29: Conteo de participantes unicos | H29: >=50 | I29: Cuantitativa directa | J29: Registro de movilidad y actividades internacionales | K29: Division of Student Services / Division of Academic Affairs | L29: Ronald | M29: Anual | N29: 3 | O29: Meet and Greet, Congresos, American experience -New Business Leaders for a New World: 3 | Q29: Parcialmente Cumplido | R29: TRUE
C30: 5 | D30: E5-O01 | E30: Operativo | F30: Convenios activos: Convenios vigentes | G30: Conteo de convenios activos y verificados | H30: >=20 | I30: Cuantitativa directa | J30: Registro de convenios; actas; productos y reportes | K30: Division of Admissions and Marketing | L30: Antony Huaynapata | M30: Anual | N30: 15 | O30: CONVENIOS ACTIVOS VERIFICADOS | P30: =20-N30 -> 5 | Q30: Parcialmente Cumplido | R30: TRUE
A31: E6. Cultura Universitaria | B31: Promover una cultura ética, inclusiva, diversa y con sentido de pertenencia. | C31: 1 | D31: E6-I01 | E31: Institucional | F31: Sentido de pertenencia: Percepcion de estudiantes, faculty y staff sobre identificacion, inclusion y vinculacion con la comunidad BGU. | G31: Respuestas favorables / respuestas validas x 100 | H31: >=85% | I31: Cuantitativa indirecta | J31: Encuesta institucional de cultura y pertenencia | K31: President / Division of Student Services | L31: Marisol | M31: Anual | N31: 0 | O31: Se recomienda incluir: ¿Qué tan identificado/a se siente con los valores y la comunidad de Blackwell Global University? | Q31: No cumplido | R31: TRUE
C32: 2 | D32: E6-S01 | E32: Estratégico | F32: Indice de valores eticos y transversales (IVET): Desarrollo percibido y evidenciado de fraternidad, etica, crecimiento, inclusion, diversidad, compromiso y excelencia. | G32: (Suma de puntuaciones promedio / número de valores) x 100 / 5 | H32: >=85% | I32: Mixta directa e indirecta | J32: Rubricas, encuestas y evidencias de actividades formativas | K32: Division of Academic Affairs / Compliance | L32: Marisol | M32: Anual | N32: 0 | O32: (11) ¿Qué sugerencia tendría para mejorar o fortalecer la misión, visión, valores u objetivos institucionales? Menciona los valores, pero es una pregunta abierta y no permite calcular el IVET. | Q32: No cumplido | R32: TRUE
C33: 3 | D33: E6-O01 | E33: Operativo | F33: Capacitacion anual en etica e inclusion: Cumplimiento de la formacion obligatoria en etica, inclusion, integridad academica y conducta institucional. | G33: Personas que completan / personas obligadas x 100 | H33: >=90% | I33: Cuantitativa directa | J33: Registros de capacitación y certificados | K33: Compliance / Division of Administration Services and Finance | L33: Yajayra | M33: Anual | N33: 0 | O33: No se realizaron capacitaciones en ética e inclusión. | Q33: No cumplido | R33: TRUE
A34: E7. Apoyo Económico y Acceso | B34: Brindar apoyo económico transparente y sostenible que favorezca acceso y persistencia. | C34: 1 | D34: E7-I01 | E34: Institucional | F34: Persistencia de beneficiarios de apoyo: Continuidad academica de estudiantes que reciben becas, subsidios u otra ayuda institucional. | G34: Beneficiarios que continuan / beneficiarios elegibles iniciales x 100 | H34: >=85% | I34: Cuantitativa directa | J34: SIS/SMS; registro de beneficiarios | K34: Division of Student Services / Administration Services and Finance | L34: Marisol | M34: Anual | N34: 0.91 | O34: Ratios 801 Data Collection (18.11.25) .xlsx | Q34: Cumplido | R34: TRUE
C35: 2 | D35: E7-S01 | E35: Estratégico | F35: Satisfaccion con el apoyo economico y el acceso: Valoracion de claridad, oportunidad, equidad y utilidad del proceso de ayuda. | G35: Respuestas favorables / respuestas validas x 100 | H35: >=85% | I35: Cuantitativa indirecta | J35: Encuesta a beneficiarios y solicitantes | K35: Division of Student Services / Administration Services and Finance | L35: Yajayra | M35: Anual | N35: 0 | O35: No se corrió encuesta de Satisfaccion con el apoyo economico y el acceso. | Q35: No cumplido | R35: TRUE
C36: 3 | D36: E7-O01 | E36: Operativo | F36: Fondos destinados a becas y subsidios: Valor total de ayuda reconocida durante el periodo, con metodologia financiera documentada. | G36: Suma validada de ayudas otorgadas; separar efectivo, descuento y exoneracion | H36: USD 3.6 M | I36: Cuantitativa directa | J36: Registros financieros y de ayuda estudiantil | K36: Division of Administration Services and Finance | L36: Yajayra | M36: Anual | N36: USD 3,90 M | O36: Reporte: Monto Total de GRANT Reporte Consolidado de Admisión: Reporte Consolidado de Admisión Blackwell Global University | Q36: Cumplido | R36: TRUE
C37: 4 | D37: E7-O0 | E37: Operativo | F37: Fondos recibidos de donantes: Recursos efectivamente recibidos de terceros para apoyar acceso, becas o iniciativas estudiantiles. | G37: Suma de ingresos recibidos y conciliados | H37: USD 0.2 M | I37: Cuantitativa directa | J37: Contabilidad; contratos y recibos de donacion | K37: Division of Administration Services and Finance / President | L37: Yajayra | M37: Anual | N37: USD 0 M | O37: No se han recibido recursos de donantes | Q37: No cumplido | R37: TRUE
F38: Total | G38: 34

Sheet Registro Datos - NO VALIDO
A1: PLAN DE EFECTIVIDAD VIGENTE 2025 - 2026 | C1: Plan de Efectividad Institucional de BGU Año Académico 2025-2026 (30.12.25)
A2: Código | B2: Dimensión | C2: Indicador | D2: Meta esperada | E2: Temporalidad | F2: División BGU | G2: RESULTADOS ALCANZADOS | H2: FUENTES DE VERIFICACIÓN | I2: COMENTARIOS RELEVANTES | J2: ACCIONES DE MEJORA IDENTIFICADAS
A3: 46023 | B3: Portafolio académico | C3: Pertinencia Curricular Internacional | D3: ≥4/5 | E3: Anual | F3: Division of Academic Affairs
A4: 46054 | B4: Portafolio académico | C4: Diversificación Lingüística | D4: ≥30% | E4: Anual | F4: Division of Academic Affairs
A5: 46082 | B5: Portafolio académico | C5: Innovación Curricular Percibida | D5: ≥4/5 | E5: Anual | F5: Division of Academic Affairs
A6: 46113 | B6: Portafolio académico | C6: Flexibilidad Académica | D6: ≥80% satisfechos | E6: Anual | F6: Division of Academic Affairs
A7: 46143 | B7: Portafolio académico | C7: Reputación Académica Externa | D7: ≥4/5 | E7: Anual | F7: Division of Academic Affairs
A8: 46174 | B8: Portafolio académico | C8: Nº Programas Autorizados (CIE) | D8: ≥11 | E8: Anual | F8: Division of Academic Affairs
A9: 46204 | B9: Portafolio académico | C9: Graduation Rate General | D9: ≥70% | E9: Anual | F9: Division of Student Services | G9: 0.1246 | H9: RATIOS 01/07/2025 to 30/06/2026
A10: 46235 | B10: Portafolio académico | C10: Retention Rate Estudiantil | D10: ≥85% | E10: Anual | F10: Division of Student Services | G10: 0.9112 | H10: RATIOS 01/07/2025 to 30/06/2026
A11: 46266 | B11: Portafolio académico | C11: Diversidad Geográfica | D11: ≥20 países | E11: Anual | F11: Division of Admissions/Marketing | G11: Reporte consolidado de admisión: https://docs.google.com/spreadsheets/d/1D3xU22BJJ-9-PmpUytOa9QaXz1SqTwSGFxc5l8YFYfw/edit?gid=1233620087#gid=1233620087 | H11: Registro de admisión
A12: 46296 | B12: Portafolio académico | C12: Oferta Efectiva de Programas | D12: ≥59% | E12: Anual | F12: Division of Admissions/Marketing | G12: https://proxy.blackwell.university/?url=https://web02.fldoe.org/CIE/SearchSchools/SchoolSearchDetail.aspx?schoolID=12499 | H12: Información de la Commission For Independent Education | I12: Todos los programas activos.
A13: 46055 | B13: Claustro Académico | C13: Actualización Pedagógica | D13: ≥70% | E13: Anual | F13: División de Educación Continua
A14: 46083 | B14: Claustro Académico | C14: Diversidad Internacional | D14: ≥10 países | E14: Anual | F14: Division of Academic Affairs
A15: 46114 | B15: Claustro Académico | C15: Innovación Didáctica | D15: ≥4/5 | E15: Anual | F15: Division of Academic Affairs
A16: 46144 | B16: Claustro Académico | C16: Reconocimiento Externo del Claustro | D16: ≥4/5 | E16: Anual | F16: Division of Academic Affairs
A17: 46175 | B17: Claustro Académico | C17: % Profesores Top en Actividad | D17: ≥10% | E17: Anual | F17: Division of Academic Affairs
A18: 46205 | B18: Claustro Académico | C18: Permanencia Docente | D18: ≥85% | E18: Anual | F18: Division of Academic Affairs
A19: 46236 | B19: Claustro Académico | C19: Producción Científica | D19: ≥2 | E19: Anual | F19: Division of Academic Affairs
A20: 46267 | B20: Claustro Académico | C20: Satisfacción Académica | D20: ≥80% satisfechos | E20: Anual | F20: Division of Student Services | G20: Pendiente | H20: ERP BGU | I20: Encuesta en aplicación
A21: 46297 | B21: Claustro Académico | C21: Graduation Rate Posgrado | D21: ≥70% | E21: Anual | F21: Division of Student Services | G21: 0.875 | H21: RATIOS 01/07/2025 to 30/06/2026
A22: 46025 | B22: Capital Humano (Administrativo) | C22: Satisfacción con Central de Atención | D22: ≥4/5 | E22: Anual | F22: Division of Student Services | G22: Pendiente | H22: ERP BGU | I22: Encuesta en aplicación
A23: 46056 | B23: Capital Humano (Administrativo) | C23: Innovación Administrativa | D23: ≥6 | E23: Anual | F23: Division of Administration Services and Finance | G23: Reporte-15: https://docs.google.com/spreadsheets/d/1bLeOhiiIGSdhKg4g2lTu5em_xjEiKNEbRTOZYACUr88/edit?gid=359438294#gid=359438294 | H23: Reporte ACP SGC Bitrix
A24: 46084 | B24: Capital Humano (Administrativo) | C24: Accesibilidad de Servicios | D24: ≥85% | E24: Anual | F24: Division of Administration Services and Finance | G24: Sí se tiene la herramienta, sin embargo, aún no se tienen resultados | H24: Encuesta anual de satisfacción estudiantil / Informe Servicio al Estudiante | I24: Pregunta 16: https://docs.google.com/document/d/1eYH7OC0sK7pUDE-0Dis7DxZhq9HZ1MJAJrtAWZuIggM/edit?tab=t.0
A25: 46115 | B25: Capital Humano (Administrativo) | C25: Clima Laboral Administrativo | D25: ≥85% | E25: Anual | F25: Division of Administration Services and Finance | G25: 96,69% Informe: https://drive.google.com/file/d/15N5BwJ16rYWiTDyLzCRv9q-1AkMQxCM5/view?usp=drive_link Encuesta: https://drive.google.com/file/d/1id6MP22lDL-oL7ut2DuyCblQVOa6L3c4/view?usp=drive_link | H25: Informe de Encuesta anual al staff
A26: 46145 | B26: Capital Humano (Administrativo) | C26: Imagen Institucional Administrativa | D26: ≥85% | E26: Anual | F26: Division of Administration Services and Finance | G26: Sí se tiene la herramienta, sin embargo, aún no se tienen resultados | H26: Encuesta anual de satisfacción estudiantil / Informe Servicio al Estudiante | I26: Pregunta 11, 13 y 16: https://docs.google.com/document/d/1eYH7OC0sK7pUDE-0Dis7DxZhq9HZ1MJAJrtAWZuIggM/edit?tab=t.0
A27: 46176 | B27: Capital Humano (Administrativo) | C27: Capacitación Administrativa | D27: ≥80% | E27: Anual | F27: Division of Administration Services and Finance | G27: Informe con corte a Junio 2026 - 90%: https://docs.google.com/document/d/1ZNoM3Axx9AGv8Mab3N0cNxaGwCUcmTT-tSdI1w5UzS0/edit?tab=t.0 | H27: Informe anual de la ejecución del Plan de Capacitación RRHH
A28: 46206 | B28: Capital Humano (Administrativo) | C28: Resolución en Primer Contacto | D28: ≥70% | E28: Anual | F28: Division of Administration Services and Finance | G28: Reporte Zoho Desk - 75%: https://drive.google.com/file/d/1IcrzjQ2kybNCy7FDUZrIirYl6sUf1ehy/view?usp=drive_link | H28: Reporte Zoho Desk
A29: 46237 | B29: Capital Humano (Administrativo) | C29: Tiempo Medio de Respuesta | D29: ≤6h | E29: Anual | F29: Division of Administration Services and Finance | G29: Reporte Zoho Desk - 2h 39m: https://drive.google.com/file/d/1bWqmY7uuv-dGqXW2yYjRyVcRxm2UHCgF/view?usp=drive_link | H29: Reporte Zoho Desk
A30: 46268 | B30: Capital Humano (Administrativo) | C30: Retention Rate Administrativo | D30: ≥85% | E30: Anual | F30: Division of Administration Services and Finance | G30: 90,38% Personal Administrativo: https://drive.google.com/file/d/1xbTlC_Ca29hOTgVhrDN56taBAZnvhheA/view?usp=drive_link | H30: Nómina | I30: =((104-10)/104) -> 0.90384615
A31: 46298 | B31: Capital Humano (Administrativo) | C31: Satisfacción con Servicios Administrativos | D31: ≥80% | E31: Anual | F31: Division of Administration Services and Finance | G31: Sí se tiene la herramienta, sin embargo, aún no se tienen resultados | H31: Encuesta anual de satisfacción estudiantil / Informe Servicio al Estudiante | I31: Pregunta 15: https://docs.google.com/document/d/1eYH7OC0sK7pUDE-0Dis7DxZhq9HZ1MJAJrtAWZuIggM/edit?tab=t.0
A32: 46026 | B32: Plataformas Tecnológicas | C32: Satisfacción General con Plataformas (LMS/SIS) | D32: ≥4/5 | E32: Anual | F32: Division of Student Services / Division of Academic Affairs | G32: Pendiente | H32: ERP BGU | I32: Encuesta en aplicación
A33: 46057 | B33: Plataformas Tecnológicas | C33: Seguridad Percibida | D33: ≥90% | E33: Anual | F33: Division of Student Services / Division of Academic Affairs | G33: -- | H33: -- | I33: No se aplicó encuesta
A34: 46085 | B34: Plataformas Tecnológicas | C34: Innovación Tecnológica Percibida | D34: ≥4/5 | E34: Anual | F34: Division of Student Services / Division of Academic Affairs | G34: -- | H34: -- | I34: No se aplicó encuesta
A35: 46146 | B35: Plataformas Tecnológicas | C35: Optimización de Procesos | D35: ≥5 nuevos/año | E35: Anual | F35: Division of Administration Services and Finance | H35: Informe TI
A36: 46177 | B36: Plataformas Tecnológicas | C36: Adopción y Capacitación en Plataformas | D36: ≥90% | E36: Anual | F36: Division of Academic Affairs / Division of Continuing Education
A37: 46027 | B37: Posicionamiento Global | C37: Relevancia de Alianzas | D37: ≥4/5 | E37: Anual | F37: Division of Admissions/Marketing | G37: Pregrado y Posgrado | I37: Contamos con 4 convenios activos de los cuales 1 ofrece impacto a nivel matrículas con un 73% de la participación en matriculas de pregrado.
A38: 46058 | B38: Posicionamiento Global | C38: Percepción de Marca Global | D38: ≥60% | E38: Anual | F38: Division of Admissions/Marketing | I38: En las encuestas que se han aplicado hasta el momento (registros, servicios al estudiante y marketing) no se ha considerado el item
A39: 46086 | B39: Posicionamiento Global | C39: Satisfacción de Socios | D39: ≥4/5 | E39: Anual | F39: Division of Student Services | G39: Pendiente | H39: ERP BGU | I39: Nueva Propuesta
A40: 46117 | B40: Posicionamiento Global | C40: Reconocimiento en Rankings | D40: Aparecer en un ranking | E40: Anual | F40: Division of Admissions/Marketing | I40: En el periodo Julio 2025 / Junio 2026, no estamos en ninguno y se está prospectando fuentes con RF para trabajarlas.
...

Sheet Registro Datos - Reportes semes
A1: Fecha de recepción | B1: Año académico | C1: Mes / periodo | D1: Corte asociado | E1: Código | F1: Indicador | G1: Dimensión | H1: Temporalidad | I1: División BGU | J1: Valor reportado | K1: Unidad / escala | L1: Fuente / evidencia | M1: Link / ubicación | N1: Observaciones
A2: Septiembre / Octubre 2025 | B2: 2025 - 2026 | C2: Fall | D2: Septiembre - Diciembre | E2: 46116 | F2: Disponibilidad de Sistemas Críticos (Uptime) | G2: Plataformas Tecnológicas | H2: Mensual | I2: Division of Administration Services and Finance | J2: LMS 99,99% / SIS 99.95% | K2: % | L2: Reporte de indicador mensual | M2: correo | N2: CUMPLE
A3: 45962 | B3: 2025 - 2026 | C3: Fall | D3: Septiembre - Diciembre | E3: 46116 | F3: Disponibilidad de Sistemas Críticos (Uptime) | G3: Plataformas Tecnológicas | H3: Mensual | I3: Division of Administration Services and Finance | J3: LMS 99,99% / SIS 99.94% | K3: % | L3: Reporte de indicador mensual | M3: correo | N3: CUMPLE
A4: 45992 | B4: 2025 - 2026 | C4: Fall | D4: Septiembre - Diciembre | E4: 46116 | F4: Disponibilidad de Sistemas Críticos (Uptime) | G4: Plataformas Tecnológicas | H4: Mensual | I4: Division of Administration Services and Finance | J4: LMS 99,99% / SIS 99.97% | K4: % | L4: Reporte de indicador mensual | M4: correo | N4: CUMPLE
A5: 46023 | B5: 2025 - 2026 | C5: Spring | D5: Enero - Abril | E5: 46116 | F5: Disponibilidad de Sistemas Críticos (Uptime) | G5: Plataformas Tecnológicas | H5: Mensual | I5: Division of Administration Services and Finance | J5: LMS 99,98% / SIS 99.95% | K5: % | L5: Reporte de indicador mensual | M5: correo | N5: CUMPLE
A6: 46054 | B6: 2025 - 2026 | C6: Spring | D6: Enero - Abril | E6: 46116 | F6: Disponibilidad de Sistemas Críticos (Uptime) | G6: Plataformas Tecnológicas | H6: Mensual | I6: Division of Administration Services and Finance | J6: LMS 99,98% / SIS 99.96% | K6: % | L6: Reporte de indicador mensual | M6: correo | N6: CUMPLE
A7: 46082 | B7: 2025 - 2026 | C7: Spring | D7: Enero - Abril | E7: 46116 | F7: Disponibilidad de Sistemas Críticos (Uptime) | G7: Plataformas Tecnológicas | H7: Mensual | I7: Division of Administration Services and Finance | J7: LMS 100% / SIS 100% | K7: % | L7: Reporte de indicador mensual | M7: correo | N7: CUMPLE
A8: - | B8: 2025 - 2026 | C8: Spring | D8: Enero - Abril | E8: 46116 | F8: Disponibilidad de Sistemas Críticos (Uptime) | G8: Plataformas Tecnológicas | H8: Mensual | I8: Division of Administration Services and Finance | J8: LMS 100% / SIS 100% | K8: % | L8: Reporte de indicador mensual | M8: correo | N8: CUMPLE
A9: 46029 | B9: 2025 - 2026 | C9: Fall | D9: Septiembre - Diciembre | E9: 46207 | F9: Costo de Tecnología por Estudiante | G9: Posicionamiento Global | H9: Semestral | I9: Division of Administration Services and Finance | J9: 4.95 $ | K9: $ | L9: Reporte de tecnología por estudiante | M9: correo | N9: CUMPLE
A10: - | B10: 2025 - 2026 | C10: Spring | D10: Enero - Abril | E10: 46207 | F10: Costo de Tecnología por Estudiante | G10: Posicionamiento Global | H10: Semestral | I10: Division of Administration Services and Finance | J10: 9.80 USD | K10: $ | L10: Reporte de tecnología por estudiante | M10: correo | N10: CUMPLE
A11: 46029 | B11: 2025 - 2026 | C11: Fall | D11: Septiembre - Diciembre | E11: 46239 | F11: Placement Rate | G11: Posicionamiento Global | H11: Semestral | I11: Student Services Division | J11: 0.72 | K11: % | L11: Indicadores de desempeño | M11: correo | N11: NO CUMPLE LA META >85%
A12: - | B12: 2025 - 2026 | C12: Spring | D12: Enero - Abril | E12: 46239 | F12: Placement Rate | G12: Posicionamiento Global | H12: Semestral | I12: Student Services Division | J12: PENDIENTE | K12: - | L12: - | M12: - | N12: información obtenida en MAYO 2026
A13: 46023 | B13: 2025 - 2026 | C13: Fall | D13: Septiembre - Diciembre | E13: 46024 | F13: Evaluación Docente por Estudiantes | G13: Claustro Académico | H13: Mensual | I13: Student Services Division | J13: 5 | K13: - | L13: INDICADORES DE DESEMPEÑO IEP | M13: correo | N13: CUMPLE
A14: 46023 | B14: 2025 - 2026 | C14: Fall | D14: Septiembre - Diciembre | E14: 46024 | F14: Evaluación Docente por Estudiantes | G14: Claustro Académico | H14: Mensual | I14: Student Services Division | J14: 5 | K14: - | L14: INDICADORES DE DESEMPEÑO IEP | M14: correo | N14: CUMPLE
A15: 46023 | B15: 2025 - 2026 | C15: Fall | D15: Septiembre - Diciembre | E15: 46024 | F15: Evaluación Docente por Estudiantes | G15: Claustro Académico | H15: Mensual | I15: Student Services Division | J15: 5 | K15: - | L15: INDICADORES DE DESEMPEÑO IEP | M15: correo | N15: CUMPLE
A16: 46023 | B16: 2025 - 2026 | C16: Fall | D16: Septiembre - Diciembre | E16: 46024 | F16: Evaluación Docente por Estudiantes | G16: Claustro Académico | H16: Mensual | I16: Student Services Division | J16: 4 | K16: - | L16: INDICADORES DE DESEMPEÑO IEP | M16: correo | N16: CUMPLE
A17: - | B17: 2025 - 2026 | C17: Spring | D17: Enero - Abril | E17: 46024 | F17: Evaluación Docente por Estudiantes | G17: Claustro Académico | H17: Mensual | I17: Student Services Division | J17: 4 | K17: - | L17: INDICADORES DE DESEMPEÑO IEP | M17: correo | N17: CUMPLE
A18: - | B18: 2025 - 2026 | C18: Spring | D18: Enero - Abril | E18: 46024 | F18: Evaluación Docente por Estudiantes | G18: Claustro Académico | H18: Mensual | I18: Student Services Division | J18: 5 | K18: - | L18: INDICADORES DE DESEMPEÑO IEP | M18: correo | N18: CUMPLE
A19: - | B19: 2025 - 2026 | C19: Spring | D19: Enero - Abril | E19: 46024 | F19: Evaluación Docente por Estudiantes | G19: Claustro Académico | H19: Mensual | I19: Student Services Division | J19: 4.62 | K19: - | L19: INDICADORES DE DESEMPEÑO IEP | M19: correo | N19: CUMPLE
A20: - | B20: 2025 - 2026 | C20: Spring | D20: Enero - Abril | E20: 46024 | F20: Evaluación Docente por Estudiantes | G20: Claustro Académico | H20: Mensual | I20: Student Services Division | J20: - | K20: - | L20: - | M20: - | N20: información obtenida en MAYO 2026
A21: - | B21: 2025 - 2026 | C21: Fall | D21: Septiembre - Diciembre | E21: 46270 | F21: Participación de BGU en foros/seminarios internacionales | G21: Posicionamiento Global | H21: Semestral | I21: Academic Affairs Division | J21: - | K21: - | L21: - | M21: - | N21: No reportó
A22: - | B22: 2025 - 2026 | C22: Spring | D22: Enero - Abril | E22: 46270 | F22: Participación de BGU en foros/seminarios internacionales | G22: Posicionamiento Global | H22: Semestral | I22: Academic Affairs Division | J22: - | K22: - | L22: - | M22: - | N22: No reportó
A23: 46082 | B23: 2025 - 2026 | C23: Spring | D23: Enero - Abril | E23: 46266 | F23: Diversidad Geográfica | G23: Portafolio Académico | H23: Anual | I23: Admissions and Marketing Division | J23: 20 | K23: N° | L23: Plan de Efectividad Institucional de BGU Año Académico 2025-2026 (30.12.25) | M23: Drive | N23: Avance
A24: 46082 | B24: 2025 - 2026 | C24: Spring | D24: Enero - Abril | E24: 46296 | F24: Oferta Efectiva de Programas | G24: Portafolio Académico | H24: Anual | I24: Admissions and Marketing Division | J24: 1 | K24: % | L24: Plan de Efectividad Institucional de BGU Año Académico 2025-2026 (30.12.25) | M24: Drive | N24: Avance
A25: 46082 | B25: 2025 - 2026 | C25: Spring | D25: Enero - Abril | E25: 46027 | F25: Impacto académico de convenios | G25: Posicionamiento Global | H25: Anual | I25: Admissions and Marketing Division | J25: 46143 | K25: N° | L25: Pregrado y Posgrado | M25: Drive | N25: Avance
A26: 46082 | B26: 2025 - 2026 | C26: Spring | D26: Enero - Abril | E26: 46058 | F26: Opinión sobre visibilidad internacional Asociación de marca | G26: Posicionamiento Global | H26: Anual | I26: Admissions and Marketing Division | J26: en proceso | K26: - | L26: - | M26: - | N26: Avance
A27: 46082 | B27: 2025 - 2026 | C27: Spring | D27: Enero - Abril | E27: 46117 | F27: Posición en rankings | G27: Posicionamiento Global | H27: Anual | I27: Admissions and Marketing Division | J27: 0 | K27: - | L27: - | M27: - | N27: Avance
A28: 46082 | B28: 2025 - 2026 | C28: Spring | D28: Enero - Abril | E28: 46178 | F28: Cantidad de convenios activos | G28: Posicionamiento Global | H28: Anual | I28: Admissions and Marketing Division | J28: 4 | K28: N° | L28: DDI.PR.01.RG.01 Control de Suscripción de Convenios Nacionales e Internacionales Rev.00_2026 | M28: Drive | N28: Avance
A29: 46082 | B29: 2025 - 2026 | C29: Spring | D29: Enero - Abril | E29: 46115 | F29: Clima Laboral Administrativo | G29: Capital Humano | H29: Anual | I29: Division of Administration Services and Finance | J29: en proceso | K29: % | L29: Informe sobre la encuesta de Clima Laboral | M29: correo | N29: Avance
B31: 2025 - 2026 | C31: Summer | D31: Mayo | E31: 46024 | F31: Evaluación Docente por Estudiantes | G31: Claustro Académico | H31: Mensual | I31: Student Services Division | J31: Pendiente
B32: 2025 - 2026 | C32: Summer | D32: Junio | E32: 46024 | F32: Evaluación Docente por Estudiantes | G32: Claustro Académico | H32: Mensual | I32: Student Services Division | J32: Pendiente
B33: 2025 - 2026 | C33: Summer | D33: Julio | E33: 46024 | F33: Evaluación Docente por Estudiantes | G33: Claustro Académico | H33: Mensual | I33: Student Services Division | J33: Pendiente
B34: 2025 - 2026 | C34: Summer | D34: Agosto | E34: 46024 | F34: Evaluación Docente por Estudiantes | G34: Claustro Académico | H34: Mensual | I34: Student Services Division | J34: Pendiente
B35: 2025 - 2026 | C35: Summer | D35: Mayo | E35: 46116 | F35: Disponibilidad de Sistemas Críticos (Uptime) | G35: Plataformas Tecnológicas | H35: Mensual | I35: Division of Administration Services and Finance | J35: Pendiente
B36: 2025 - 2026 | C36: Summer | D36: Junio | E36: 46116 | F36: Disponibilidad de Sistemas Críticos (Uptime) | G36: Plataformas Tecnológicas | H36: Mensual | I36: Division of Administration Services and Finance | J36: Pendiente
B37: 2025 - 2026 | C37: Summer | D37: Julio | E37: 46116 | F37: Disponibilidad de Sistemas Críticos (Uptime) | G37: Plataformas Tecnológicas | H37: Mensual | I37: Division of Administration Services and Finance | J37: Pendiente
B38: 2025 - 2026 | C38: Summer | D38: Agosto | E38: 46116 | F38: Disponibilidad de Sistemas Críticos (Uptime) | G38: Plataformas Tecnológicas | H38: Mensual | I38: Division of Administration Services and Finance | J38: Pendiente
B39: 2025 - 2026 | C39: Summer | D39: Mayo - Julio | E39: 46207 | F39: Costo de Tecnología por Estudiante | G39: Posicionamiento Global | H39: Semestral | I39: Division of Administration Services and Finance | J39: Pendiente
B40: 2025 - 2026 | C40: Summer | D40: Mayo - Julio | E40: 46239 | F40: Placement Rate | G40: Posicionamiento Global | H40: Semestral | I40: Student Services Division | J40: Pendiente
F50: {=IFERROR(XLOOKUP(E50,'Indicadores Master'!$D$2:$D$65,'Indicadores Master'!$E$2:$E$65,""),"")} | G50: {=IFERROR(XLOOKUP(E50,'Indicadores Master'!$D$2:$D$65,'Indicadores Master'!$A$2:$A$65,""),"")}
...

Sheet Evaluación Cortes Semestrales
A1: Matriz de análisis y evaluación formal del Plan de Efectividad
A3: Código | B3: Dimensión | C3: Indicador | D3: Temporalidad | E3: Meta esperada | F3: División BGU | G3: C1 - Diciembre | N3: C2 - Abril | U3: C3 - Agosto
